#VRML_SIM R2019a utf8
WorldInfo {
}
Viewpoint {
  orientation -0.17931621899006708 0.9710069033393681 0.15808632854993337 1.4349704398151548
  position 1.535551017473615 0.47510865313965833 0.21097930140629817
}
TexturedBackground {
}
TexturedBackgroundLight {
}
Floor {
}
Robot {
  translation 0 0.035 0
  rotation 1 0 0 0
  children [
    DEF ROBOT_BODY Shape {
      appearance PBRAppearance {
      }
      geometry DEF G_BODY Box {
        size 0.25 0.07 0.1
      }
    }
    DEF WHEEL_JOINT HingeJoint {
      jointParameters HingeJointParameters {
        axis 0 0 1
        anchor -0.05 0 0.06
      }
      device [
        RotationalMotor {
          name "motor_right"
        }
      ]
      endPoint DEF WHEEL_1 Solid {
        translation -0.05 0 0.06
        rotation 1 0 0 1.57
        children [
          Shape {
            appearance PBRAppearance {
              baseColor 0 0 0
              roughness 1
              metalness 0
            }
            geometry DEF G_WHEEL Cylinder {
              height 0.02
              radius 0.075
            }
          }
        ]
        boundingObject USE G_WHEEL
        physics Physics {
        }
      }
    }
  ]
  boundingObject USE G_BODY
  physics Physics {
  }
  controller "Robot1"
}
