#VRML_SIM R2019a utf8
WorldInfo {
}
Viewpoint {
  orientation -0.07872928204153981 0.9661959069355058 0.24549372613225523 2.51573661358599
  position 1.0968403797568467 0.6598200183240053 -0.7130804962360257
}
TexturedBackground {
}
TexturedBackgroundLight {
}
Floor {
}
Robot {
  translation 0 0.035 0
  rotation 1 0 0 0
  children [
    DEF ROBOT_BODY Shape {
      appearance PBRAppearance {
      }
      geometry DEF G_BODY Box {
        size 0.25 0.07 0.1
      }
    }
    DEF WHEEL_JOINT HingeJoint {
      jointParameters HingeJointParameters {
        axis 0 0 1
        anchor -0.05 0 0.06
      }
      device [
        RotationalMotor {
          name "motor_right"
        }
      ]
      endPoint DEF WHEEL_1 Solid {
        translation -0.05 0 0.06
        rotation 0.40779432835262774 0.6453835623758893 -0.6458977033388769 3.9165647108573847
        children [
          DEF SHAPE_WHEEL Shape {
            appearance PBRAppearance {
              baseColor 0 0 0
              roughness 1
              metalness 0
            }
            geometry DEF G_WHEEL Cylinder {
              height 0.02
              radius 0.075
            }
          }
        ]
        boundingObject USE G_WHEEL
        physics Physics {
        }
      }
    }
    DEF WHEEL_2_JOINT HingeJoint {
      jointParameters HingeJointParameters {
        axis 0 0 1
        anchor -0.05 0 -0.06
      }
      device [
        RotationalMotor {
          name "motor_left"
        }
      ]
      endPoint Solid {
        translation -0.05 0 -0.06
        rotation 1 0 0 1.57
        children [
          USE SHAPE_WHEEL
        ]
        name "solid(1)"
        boundingObject USE SHAPE_WHEEL
        physics Physics {
        }
      }
    }
  ]
  boundingObject USE G_BODY
  physics Physics {
  }
  controller "Robot1"
}
