#VRML_SIM R2019a utf8
WorldInfo {
}
Viewpoint {
  orientation -0.10448768814122152 0.9738162301294405 0.20190164180458622 2.1775591014614806
  position 1.6277672290629328 0.6079710051730546 -1.101515471621672
}
TexturedBackground {
}
TexturedBackgroundLight {
}
Floor {
}
Robot {
  translation 0 0.08 0
  rotation 1 0 0 0
  children [
    DEF GR_BODY Group {
      children [
        DEF ROBOT_BODY Shape {
          appearance PBRAppearance {
          }
          geometry DEF G_BODY Box {
            size 0.25 0.07 0.1
          }
        }
        Transform {
          translation 0.11 -0.05 0
          children [
            Shape {
              appearance PBRAppearance {
                baseColor 0 0 0
                roughness 1
                metalness 0
              }
              geometry Sphere {
                radius 0.03
              }
            }
          ]
        }
      ]
    }
    DEF WHEEL_JOINT HingeJoint {
      jointParameters HingeJointParameters {
        axis 0 0 1
        anchor -0.05 0 0.06
      }
      device [
        RotationalMotor {
          name "motor_right"
        }
      ]
      endPoint DEF WHEEL_1 Solid {
        translation -0.05 0 0.06
        rotation 0.40779432835262774 0.6453835623758893 -0.6458977033388769 3.9165647108573847
        children [
          DEF SHAPE_WHEEL Shape {
            appearance PBRAppearance {
              baseColor 0 0 0
              roughness 1
              metalness 0
            }
            geometry DEF G_WHEEL Cylinder {
              height 0.02
              radius 0.075
            }
          }
        ]
        boundingObject USE G_WHEEL
        physics Physics {
        }
      }
    }
    DEF WHEEL_2_JOINT HingeJoint {
      jointParameters HingeJointParameters {
        axis 0 0 1
        anchor -0.05 0 -0.06
      }
      device [
        RotationalMotor {
          name "motor_left"
        }
      ]
      endPoint Solid {
        translation -0.05 0 -0.06
        rotation 1 0 0 1.57
        children [
          USE SHAPE_WHEEL
        ]
        name "solid(1)"
        boundingObject USE SHAPE_WHEEL
        physics Physics {
        }
      }
    }
  ]
  boundingObject USE GR_BODY
  physics Physics {
  }
  controller "Robot1"
}
